Traceback (most recent call last):
  File "/home/iridium/anaconda3/lib/python3.7/site-packages/jupyter_cache/executors/utils.py", line 56, in single_nb_execution
    record_timing=False,
  File "/home/iridium/anaconda3/lib/python3.7/site-packages/nbclient/client.py", line 1087, in execute
    return NotebookClient(nb=nb, resources=resources, km=km, **kwargs).execute()
  File "/home/iridium/anaconda3/lib/python3.7/site-packages/nbclient/util.py", line 74, in wrapped
    return just_run(coro(*args, **kwargs))
  File "/home/iridium/anaconda3/lib/python3.7/site-packages/nbclient/util.py", line 53, in just_run
    return loop.run_until_complete(coro)
  File "/home/iridium/anaconda3/lib/python3.7/asyncio/base_events.py", line 583, in run_until_complete
    return future.result()
  File "/home/iridium/anaconda3/lib/python3.7/site-packages/nbclient/client.py", line 541, in async_execute
    cell, index, execution_count=self.code_cells_executed + 1
  File "/home/iridium/anaconda3/lib/python3.7/site-packages/nbclient/client.py", line 832, in async_execute_cell
    self._check_raise_for_error(cell, exec_reply)
  File "/home/iridium/anaconda3/lib/python3.7/site-packages/nbclient/client.py", line 740, in _check_raise_for_error
    raise CellExecutionError.from_cell_and_msg(cell, exec_reply['content'])
nbclient.exceptions.CellExecutionError: An error occurred while executing the following cell:
------------------
data.map(dB_convert)
------------------

[0;31m---------------------------------------------------------------------------[0m
[0;31mAttributeError[0m                            Traceback (most recent call last)
[0;32m<ipython-input-14-a5ad0e96e12f>[0m in [0;36m<module>[0;34m[0m
[0;32m----> 1[0;31m [0mdata[0m[0;34m.[0m[0mmap[0m[0;34m([0m[0mdB_convert[0m[0;34m)[0m[0;34m[0m[0;34m[0m[0m
[0m
[0;32m~/anaconda3/lib/python3.7/site-packages/pandas/core/generic.py[0m in [0;36m__getattr__[0;34m(self, name)[0m
[1;32m   5137[0m             [0;32mif[0m [0mself[0m[0;34m.[0m[0m_info_axis[0m[0;34m.[0m[0m_can_hold_identifiers_and_holds_name[0m[0;34m([0m[0mname[0m[0;34m)[0m[0;34m:[0m[0;34m[0m[0;34m[0m[0m
[1;32m   5138[0m                 [0;32mreturn[0m [0mself[0m[0;34m[[0m[0mname[0m[0;34m][0m[0;34m[0m[0;34m[0m[0m
[0;32m-> 5139[0;31m             [0;32mreturn[0m [0mobject[0m[0;34m.[0m[0m__getattribute__[0m[0;34m([0m[0mself[0m[0;34m,[0m [0mname[0m[0;34m)[0m[0;34m[0m[0;34m[0m[0m
[0m[1;32m   5140[0m [0;34m[0m[0m
[1;32m   5141[0m     [0;32mdef[0m [0m__setattr__[0m[0;34m([0m[0mself[0m[0;34m,[0m [0mname[0m[0;34m:[0m [0mstr[0m[0;34m,[0m [0mvalue[0m[0;34m)[0m [0;34m->[0m [0;32mNone[0m[0;34m:[0m[0;34m[0m[0;34m[0m[0m

[0;31mAttributeError[0m: 'DataFrame' object has no attribute 'map'
AttributeError: 'DataFrame' object has no attribute 'map'

