Traceback (most recent call last):
  File "/home/iridium/anaconda3/lib/python3.7/site-packages/jupyter_cache/executors/utils.py", line 56, in single_nb_execution
    record_timing=False,
  File "/home/iridium/anaconda3/lib/python3.7/site-packages/nbclient/client.py", line 1087, in execute
    return NotebookClient(nb=nb, resources=resources, km=km, **kwargs).execute()
  File "/home/iridium/anaconda3/lib/python3.7/site-packages/nbclient/util.py", line 74, in wrapped
    return just_run(coro(*args, **kwargs))
  File "/home/iridium/anaconda3/lib/python3.7/site-packages/nbclient/util.py", line 53, in just_run
    return loop.run_until_complete(coro)
  File "/home/iridium/anaconda3/lib/python3.7/asyncio/base_events.py", line 583, in run_until_complete
    return future.result()
  File "/home/iridium/anaconda3/lib/python3.7/site-packages/nbclient/client.py", line 541, in async_execute
    cell, index, execution_count=self.code_cells_executed + 1
  File "/home/iridium/anaconda3/lib/python3.7/site-packages/nbclient/client.py", line 832, in async_execute_cell
    self._check_raise_for_error(cell, exec_reply)
  File "/home/iridium/anaconda3/lib/python3.7/site-packages/nbclient/client.py", line 740, in _check_raise_for_error
    raise CellExecutionError.from_cell_and_msg(cell, exec_reply['content'])
nbclient.exceptions.CellExecutionError: An error occurred while executing the following cell:
------------------
reset()
d=D(model='1N4148')
vs=V(dc_value=1@u_V)
vs['p', 'n']+=d['p'], gnd
d['n']+=gnd
circ=generate_netlist(libs='SpiceLib')
print(circ)
------------------

[0;31m---------------------------------------------------------------------------[0m
[0;31mKeyError[0m                                  Traceback (most recent call last)
[0;32m~/anaconda3/lib/python3.7/site-packages/skidl/tools/spice.py[0m in [0;36m_gen_netlist_[0;34m(self, **kwargs)[0m
[1;32m    302[0m                 [0;32mtry[0m[0;34m:[0m[0;34m[0m[0;34m[0m[0m
[0;32m--> 303[0;31m                     [0mpath[0m [0;34m=[0m [0mpyspice[0m[0;34m[[0m[0;34m"lib"[0m[0;34m][0m[0;34m[[0m[0mmodel[0m[0;34m][0m[0;34m[0m[0;34m[0m[0m
[0m[1;32m    304[0m                 [0;32mexcept[0m [0mKeyError[0m[0;34m:[0m[0;34m[0m[0;34m[0m[0m

[0;31mKeyError[0m: 'lib'

During handling of the above exception, another exception occurred:

[0;31mTypeError[0m                                 Traceback (most recent call last)
[0;32m<ipython-input-3-29be18072af7>[0m in [0;36m<module>[0;34m[0m
[1;32m      4[0m [0mvs[0m[0;34m[[0m[0;34m'p'[0m[0;34m,[0m [0;34m'n'[0m[0;34m][0m[0;34m+=[0m[0md[0m[0;34m[[0m[0;34m'p'[0m[0;34m][0m[0;34m,[0m [0mgnd[0m[0;34m[0m[0;34m[0m[0m
[1;32m      5[0m [0md[0m[0;34m[[0m[0;34m'n'[0m[0;34m][0m[0;34m+=[0m[0mgnd[0m[0;34m[0m[0;34m[0m[0m
[0;32m----> 6[0;31m [0mcirc[0m[0;34m=[0m[0mgenerate_netlist[0m[0;34m([0m[0mlibs[0m[0;34m=[0m[0;34m'SpiceLib'[0m[0;34m)[0m[0;34m[0m[0;34m[0m[0m
[0m[1;32m      7[0m [0mprint[0m[0;34m([0m[0mcirc[0m[0;34m)[0m[0;34m[0m[0;34m[0m[0m

[0;32m~/anaconda3/lib/python3.7/site-packages/skidl/circuit.py[0m in [0;36mgenerate_netlist[0;34m(self, **kwargs)[0m
[1;32m    489[0m         [0;32mtry[0m[0;34m:[0m[0;34m[0m[0;34m[0m[0m
[1;32m    490[0m             [0mgen_func[0m [0;34m=[0m [0mgetattr[0m[0;34m([0m[0mself[0m[0;34m,[0m [0;34m"_gen_netlist_{}"[0m[0;34m.[0m[0mformat[0m[0;34m([0m[0mtool[0m[0;34m)[0m[0;34m)[0m[0;34m[0m[0;34m[0m[0m
[0;32m--> 491[0;31m             [0mnetlist[0m [0;34m=[0m [0mgen_func[0m[0;34m([0m[0;34m**[0m[0mkwargs[0m[0;34m)[0m  [0;31m# Pass any remaining arguments.[0m[0;34m[0m[0;34m[0m[0m
[0m[1;32m    492[0m         [0;32mexcept[0m [0mKeyError[0m[0;34m:[0m[0;34m[0m[0;34m[0m[0m
[1;32m    493[0m             log_and_raise(

[0;32m~/anaconda3/lib/python3.7/site-packages/skidl/tools/spice.py[0m in [0;36m_gen_netlist_[0;34m(self, **kwargs)[0m
[1;32m    307[0m                         [0;31m# Read the default SPICE libraries.[0m[0;34m[0m[0;34m[0m[0;34m[0m[0m
[1;32m    308[0m                         [0;32mfor[0m [0mpath[0m [0;32min[0m [0mlib_search_paths[0m[0;34m[[0m[0mSPICE[0m[0;34m][0m[0;34m:[0m[0;34m[0m[0;34m[0m[0m
[0;32m--> 309[0;31m                             [0mdefault_libs[0m[0;34m.[0m[0mappend[0m[0;34m([0m[0mSpiceLibrary[0m[0;34m([0m[0mroot_path[0m[0;34m=[0m[0mpath[0m[0;34m,[0m [0mrecurse[0m[0;34m=[0m[0;32mTrue[0m[0;34m)[0m[0;34m)[0m[0;34m[0m[0;34m[0m[0m
[0m[1;32m    310[0m [0;34m[0m[0m
[1;32m    311[0m                     [0;31m# Search for the model in the default libraries.[0m[0;34m[0m[0;34m[0m[0;34m[0m[0m

[0;31mTypeError[0m: __init__() got an unexpected keyword argument 'recurse'
TypeError: __init__() got an unexpected keyword argument 'recurse'

